Workbook

Sheet Employees
A1: EmployeeID | B1: FirstName | C1: LastName | D1: Gender | E1: Age | F1: DepartmentID | G1: JobTitle | H1: HireDate | I1: Salary | J1: City | K1: Email | L1: Status | M1: DEPARTMENT NAME | N1: DEPARTMENT NAME USING INDEX AND MATCH | O1: DEPARTMENT NAME (Q1 - XLOOKUP) | P1: RATING (Q2) | Q1: BONUS (Q3)
A2: E0001 | B2: Amit | C2: Dutta | D2: Female | E2: 30 | F2: D01 | G2: Analyst | H2: 2019-02-21 | I2: 105257 | J2: Kolkata | K2: amit.dutta1@example.com | L2: Active | M2: =VLOOKUP(F2,Departments!$A$1:$C$6,2,0) -> HR | N2: =INDEX(Departments!$B$1:$B$6,MATCH(Employees!F2,Departments!$A$1:$A$6,0)) -> HR | O2: =INDEX(Departments!$B$2:$B$6,MATCH(Employees!F2,Departments!$A$2:$A$6,0)) -> HR | P2: =_xlfn.XLOOKUP(A2,Performance!$A$2:$A$501,Performance!$C$2:$C$501) -> 1 | Q2: =IF(P2=5,I2*0.15,IF(P2=4,I2*0.1,IF(P2=3,I2*0.07,IF(P2<3,I2*0.05,0)))) -> 5262.85
A3: E0002 | B3: Amit | C3: Roy | D3: Male | E3: 48 | F3: D03 | G3: Executive | H3: 2021-12-18 | I3: 97903 | J3: Kolkata | K3: amit.roy2@example.com | L3: Active | M3: =VLOOKUP(F3,Departments!$A$1:$C$6,2,0) -> IT | N3: =INDEX(Departments!$B$1:$B$6, MATCH(Employees!F3, Departments!$A$1:$A$6, 0)) -> IT | O3: =INDEX(Departments!$B$2:$B$6,MATCH(Employees!F3,Departments!$A$2:$A$6,0)) -> IT | P3: =INDEX(Performance!$C$2:$C$501,MATCH(Employees!A3,Performance!$A$2:$A$501,0)) -> 4 | Q3: =IF(P3=5,I3*0.15,IF(P3=4,I3*0.1,IF(P3=3,I3*0.07,IF(P3<3,I3*0.05,0)))) -> 9790.3 | T3: HIGHLIGHT THE ACTIVE EMPLOYEE RECORD
A4: E0003 | B4: Rohit | C4: Roy | D4: Male | E4: 48 | F4: D04 | G4: Coordinator | H4: 2020-07-25 | I4: 73429 | J4: Pune | K4: rohit.roy3@example.com | L4: Inactive | M4: =VLOOKUP(F4,Departments!$A$1:$C$6,2,0) -> Sales | N4: =INDEX(Departments!$B$1:$B$6, MATCH(Employees!F4, Departments!$A$1:$A$6, 0)) -> Sales | O4: =INDEX(Departments!$B$2:$B$6,MATCH(Employees!F4,Departments!$A$2:$A$6,0)) -> Sales | P4: =INDEX(Performance!$C$2:$C$501,MATCH(Employees!A4,Performance!$A$2:$A$501,0)) -> 2 | Q4: =IF(P4=5,I4*0.15,IF(P4=4,I4*0.1,IF(P4=3,I4*0.07,IF(P4<3,I4*0.05,0)))) -> 3671.45
A5: E0004 | B5: David | C5: Dutta | D5: Female | E5: 50 | F5: D05 | G5: Manager | H5: 2021-08-05 | I5: 99336 | J5: Pune | K5: david.dutta4@example.com | L5: Active | M5: =VLOOKUP(F5,Departments!$A$1:$C$6,2,0) -> Marketing | N5: =INDEX(Departments!$B$1:$B$6, MATCH(Employees!F5, Departments!$A$1:$A$6, 0)) -> Marketing | O5: =INDEX(Departments!$B$2:$B$6,MATCH(Employees!F5,Departments!$A$2:$A$6,0)) -> Marketing | P5: =INDEX(Performance!$C$2:$C$501,MATCH(Employees!A5,Performance!$A$2:$A$501,0)) -> 4 | Q5: =IF(P5=5,I5*0.15,IF(P5=4,I5*0.1,IF(P5=3,I5*0.07,IF(P5<3,I5*0.05,0)))) -> 9933.6
A6: E0005 | B6: Jane | C6: Ghosh | D6: Male | E6: 60 | F6: D01 | G6: Coordinator | H6: 2020-06-08 | I6: 105020 | J6: Pune | K6: jane.ghosh5@example.com | L6: Active | M6: =VLOOKUP(F6,Departments!$A$1:$C$6,2,0) -> HR | N6: =INDEX(Departments!$B$1:$B$6, MATCH(Employees!F6, Departments!$A$1:$A$6, 0)) -> HR | O6: =INDEX(Departments!$B$2:$B$6,MATCH(Employees!F6,Departments!$A$2:$A$6,0)) -> HR | P6: =INDEX(Performance!$C$2:$C$501,MATCH(Employees!A6,Performance!$A$2:$A$501,0)) -> 2 | Q6: =IF(P6=5,I6*0.15,IF(P6=4,I6*0.1,IF(P6=3,I6*0.07,IF(P6<3,I6*0.05,0)))) -> 5251
A7: E0006 | B7: Rahul | C7: Dutta | D7: Male | E7: 33 | F7: D02 | G7: Coordinator | H7: 2019-08-04 | I7: 93173 | J7: Pune | K7: rahul.dutta6@example.com | L7: Active | M7: =VLOOKUP(F7,Departments!$A$1:$C$6,2,0) -> Finance | N7: =INDEX(Departments!$B$1:$B$6, MATCH(Employees!F7, Departments!$A$1:$A$6, 0)) -> Finance | O7: =INDEX(Departments!$B$2:$B$6,MATCH(Employees!F7,Departments!$A$2:$A$6,0)) -> Finance | P7: =INDEX(Performance!$C$2:$C$501,MATCH(Employees!A7,Performance!$A$2:$A$501,0)) -> 3 | Q7: =IF(P7=5,I7*0.15,IF(P7=4,I7*0.1,IF(P7=3,I7*0.07,IF(P7<3,I7*0.05,0)))) -> 6522.11
A8: E0007 | B8: Sara | C8: Ghosh | D8: Male | E8: 52 | F8: D05 | G8: Analyst | H8: 2021-01-23 | I8: 106626 | J8: Pune | K8: sara.ghosh7@example.com | L8: Active | M8: =VLOOKUP(F8,Departments!$A$1:$C$6,2,0) -> Marketing | N8: =INDEX(Departments!$B$1:$B$6, MATCH(Employees!F8, Departments!$A$1:$A$6, 0)) -> Marketing | O8: =INDEX(Departments!$B$2:$B$6,MATCH(Employees!F8,Departments!$A$2:$A$6,0)) -> Marketing | P8: =INDEX(Performance!$C$2:$C$501,MATCH(Employees!A8,Performance!$A$2:$A$501,0)) -> 2 | Q8: =IF(P8=5,I8*0.15,IF(P8=4,I8*0.1,IF(P8=3,I8*0.07,IF(P8<3,I8*0.05,0)))) -> 5331.3
A9: E0008 | B9: John | C9: Dutta | D9: Female | E9: 42 | F9: D02 | G9: Manager | H9: 2020-05-27 | I9: 114547 | J9: Delhi | K9: john.dutta8@example.com | L9: Inactive | M9: =VLOOKUP(F9,Departments!$A$1:$C$6,2,0) -> Finance | N9: =INDEX(Departments!$B$1:$B$6, MATCH(Employees!F9, Departments!$A$1:$A$6, 0)) -> Finance | O9: =INDEX(Departments!$B$2:$B$6,MATCH(Employees!F9,Departments!$A$2:$A$6,0)) -> Finance | P9: =INDEX(Performance!$C$2:$C$501,MATCH(Employees!A9,Performance!$A$2:$A$501,0)) -> 1 | Q9: =IF(P9=5,I9*0.15,IF(P9=4,I9*0.1,IF(P9=3,I9*0.07,IF(P9<3,I9*0.05,0)))) -> 5727.35
A10: E0009 | B10: John | C10: Singh | D10: Female | E10: 40 | F10: D01 | G10: Coordinator | H10: 2022-04-30 | I10: 51139 | J10: Bengaluru | K10: john.singh9@example.com | L10: Inactive | M10: =VLOOKUP(F10,Departments!$A$1:$C$6,2,0) -> HR | N10: =INDEX(Departments!$B$1:$B$6, MATCH(Employees!F10, Departments!$A$1:$A$6, 0)) -> HR | O10: =INDEX(Departments!$B$2:$B$6,MATCH(Employees!F10,Departments!$A$2:$A$6,0)) -> HR | P10: =INDEX(Performance!$C$2:$C$501,MATCH(Employees!A10,Performance!$A$2:$A$501,0)) -> 4 | Q10: =IF(P10=5,I10*0.15,IF(P10=4,I10*0.1,IF(P10=3,I10*0.07,IF(P10<3,I10*0.05,0)))) -> 5113.9
A11: E0010 | B11: Amit | C11: Roy | D11: Female | E11: 25 | F11: D05 | G11: Analyst | H11: 2018-12-23 | I11: 60673 | J11: Bengaluru | K11: amit.roy10@example.com | L11: Inactive | M11: =VLOOKUP(F11,Departments!$A$1:$C$6,2,0) -> Marketing | N11: =INDEX(Departments!$B$1:$B$6, MATCH(Employees!F11, Departments!$A$1:$A$6, 0)) -> Marketing | O11: =INDEX(Departments!$B$2:$B$6,MATCH(Employees!F11,Departments!$A$2:$A$6,0)) -> Marketing | P11: =INDEX(Performance!$C$2:$C$501,MATCH(Employees!A11,Performance!$A$2:$A$501,0)) -> 5 | Q11: =IF(P11=5,I11*0.15,IF(P11=4,I11*0.1,IF(P11=3,I11*0.07,IF(P11<3,I11*0.05,0)))) -> 9100.95
A12: E0011 | B12: Anita | C12: Roy | D12: Female | E12: 25 | F12: D05 | G12: Coordinator | H12: 2021-06-09 | I12: 65690 | J12: Kolkata | K12: anita.roy11@example.com | L12: Inactive | M12: =VLOOKUP(F12,Departments!$A$1:$C$6,2,0) -> Marketing | N12: =INDEX(Departments!$B$1:$B$6, MATCH(Employees!F12, Departments!$A$1:$A$6, 0)) -> Marketing | O12: =INDEX(Departments!$B$2:$B$6,MATCH(Employees!F12,Departments!$A$2:$A$6,0)) -> Marketing | P12: =INDEX(Performance!$C$2:$C$501,MATCH(Employees!A12,Performance!$A$2:$A$501,0)) -> 3 | Q12: =IF(P12=5,I12*0.15,IF(P12=4,I12*0.1,IF(P12=3,I12*0.07,IF(P12<3,I12*0.05,0)))) -> 4598.3
A13: E0012 | B13: Rohit | C13: Ghosh | D13: Male | E13: 49 | F13: D03 | G13: Executive | H13: 2019-02-24 | I13: 63823 | J13: Bengaluru | K13: rohit.ghosh12@example.com | L13: Active | M13: =VLOOKUP(F13,Departments!$A$1:$C$6,2,0) -> IT | N13: =INDEX(Departments!$B$1:$B$6, MATCH(Employees!F13, Departments!$A$1:$A$6, 0)) -> IT | O13: =INDEX(Departments!$B$2:$B$6,MATCH(Employees!F13,Departments!$A$2:$A$6,0)) -> IT | P13: =INDEX(Performance!$C$2:$C$501,MATCH(Employees!A13,Performance!$A$2:$A$501,0)) -> 2 | Q13: =IF(P13=5,I13*0.15,IF(P13=4,I13*0.1,IF(P13=3,I13*0.07,IF(P13<3,I13*0.05,0)))) -> 3191.15
A14: E0013 | B14: Rohit | C14: Khan | D14: Female | E14: 56 | F14: D05 | G14: Analyst | H14: 2022-03-31 | I14: 49557 | J14: Mumbai | K14: rohit.khan13@example.com | L14: Inactive | M14: =VLOOKUP(F14,Departments!$A$1:$C$6,2,0) -> Marketing | N14: =INDEX(Departments!$B$1:$B$6, MATCH(Employees!F14, Departments!$A$1:$A$6, 0)) -> Marketing | O14: =INDEX(Departments!$B$2:$B$6,MATCH(Employees!F14,Departments!$A$2:$A$6,0)) -> Marketing | P14: =INDEX(Performance!$C$2:$C$501,MATCH(Employees!A14,Performance!$A$2:$A$501,0)) -> 3 | Q14: =IF(P14=5,I14*0.15,IF(P14=4,I14*0.1,IF(P14=3,I14*0.07,IF(P14<3,I14*0.05,0)))) -> 3468.99
A15: E0014 | B15: Rohit | C15: Sen | D15: Male | E15: 44 | F15: D01 | G15: Coordinator | H15: 2022-09-23 | I15: 116901 | J15: Bengaluru | K15: rohit.sen14@example.com | L15: Active | M15: =VLOOKUP(F15,Departments!$A$1:$C$6,2,0) -> HR | N15: =INDEX(Departments!$B$1:$B$6, MATCH(Employees!F15, Departments!$A$1:$A$6, 0)) -> HR | O15: =INDEX(Departments!$B$2:$B$6,MATCH(Employees!F15,Departments!$A$2:$A$6,0)) -> HR | P15: =INDEX(Performance!$C$2:$C$501,MATCH(Employees!A15,Performance!$A$2:$A$501,0)) -> 2 | Q15: =IF(P15=5,I15*0.15,IF(P15=4,I15*0.1,IF(P15=3,I15*0.07,IF(P15<3,I15*0.05,0)))) -> 5845.05
... A24: E0023 | B24: Anita | C24: Singh | D24: Male | E24: 45 | F24: D04 | G24: Executive | H24: 2021-12-22 | I24: 51414 | J24: Bengaluru | K24: anita.singh23@example.com | L24: Active | M24: =VLOOKUP(F24,Departments!$A$1:$C$6,2,0) -> Sales | N24: =INDEX(Departments!$B$1:$B$6, MATCH(Employees!F24, Departments!$A$1:$A$6, 0)) -> Sales | O24: =INDEX(Departments!$B$2:$B$6,MATCH(Employees!F24,Departments!$A$2:$A$6,0)) -> Sales | P24: =INDEX(Performance!$C$2:$C$501,MATCH(Employees!A24,Performance!$A$2:$A$501,0)) -> 3 | Q24: =IF(P24=5,I24*0.15,IF(P24=4,I24*0.1,IF(P24=3,I24*0.07,IF(P24<3,I24*0.05,0)))) -> 3598.98
A25: E0024 | B25: Jane | C25: Singh | D25: Male | E25: 35 | F25: D02 | G25: Analyst | H25: 2019-06-08 | I25: 79578 | J25: Kolkata | K25: jane.singh24@example.com | L25: Inactive | M25: =VLOOKUP(F25,Departments!$A$1:$C$6,2,0) -> Finance | N25: =INDEX(Departments!$B$1:$B$6, MATCH(Employees!F25, Departments!$A$1:$A$6, 0)) -> Finance | O25: =INDEX(Departments!$B$2:$B$6,MATCH(Employees!F25,Departments!$A$2:$A$6,0)) -> Finance | P25: =_xlfn.XLOOKUP(A25,Performance!$A$2:$A$501,Performance!$C$2:$C$501) -> 4 | Q25: =IF(P25=5,I25*0.15,IF(P25=4,I25*0.1,IF(P25=3,I25*0.07,IF(P25<3,I25*0.05,0)))) -> 7957.8
A26: E0025 | B26: Anita | C26: Sen | D26: Male | E26: 47 | F26: D03 | G26: Specialist | H26: 2021-12-07 | I26: 111899 | J26: Bengaluru | K26: anita.sen25@example.com | L26: Inactive | M26: =VLOOKUP(F26,Departments!$A$1:$C$6,2,0) -> IT | N26: =INDEX(Departments!$B$1:$B$6, MATCH(Employees!F26, Departments!$A$1:$A$6, 0)) -> IT | O26: =INDEX(Departments!$B$2:$B$6,MATCH(Employees!F26,Departments!$A$2:$A$6,0)) -> IT | P26: =INDEX(Performance!$C$2:$C$501,MATCH(Employees!A26,Performance!$A$2:$A$501,0)) -> 4 | Q26: =IF(P26=5,I26*0.15,IF(P26=4,I26*0.1,IF(P26=3,I26*0.07,IF(P26<3,I26*0.05,0)))) -> 11189.9
A27: E0026 | B27: John | C27: Dutta | D27: Male | E27: 47 | F27: D04 | G27: Executive | H27: 2023-06-24 | I27: 95862 | J27: Kolkata | K27: john.dutta26@example.com | L27: Active | M27: =VLOOKUP(F27,Departments!$A$1:$C$6,2,0) -> Sales | N27: =INDEX(Departments!$B$1:$B$6, MATCH(Employees!F27, Departments!$A$1:$A$6, 0)) -> Sales | O27: =INDEX(Departments!$B$2:$B$6,MATCH(Employees!F27,Departments!$A$2:$A$6,0)) -> Sales | P27: =INDEX(Performance!$C$2:$C$501,MATCH(Employees!A27,Performance!$A$2:$A$501,0)) -> 1 | Q27: =IF(P27=5,I27*0.15,IF(P27=4,I27*0.1,IF(P27=3,I27*0.07,IF(P27<3,I27*0.05,0)))) -> 4793.1
A28: E0027 | B28: Amit | C28: Sen | D28: Female | E28: 49 | F28: D03 | G28: Analyst | H28: 2020-10-09 | I28: 110397 | J28: Mumbai | K28: amit.sen27@example.com | L28: Inactive | M28: =VLOOKUP(F28,Departments!$A$1:$C$6,2,0) -> IT | N28: =INDEX(Departments!$B$1:$B$6, MATCH(Employees!F28, Departments!$A$1:$A$6, 0)) -> IT | O28: =INDEX(Departments!$B$2:$B$6,MATCH(Employees!F28,Departments!$A$2:$A$6,0)) -> IT | P28: =INDEX(Performance!$C$2:$C$501,MATCH(Employees!A28,Performance!$A$2:$A$501,0)) -> 1 | Q28: =IF(P28=5,I28*0.15,IF(P28=4,I28*0.1,IF(P28=3,I28*0.07,IF(P28<3,I28*0.05,0)))) -> 5519.85
A29: E0028 | B29: Jane | C29: Das | D29: Female | E29: 27 | F29: D02 | G29: Executive | H29: 2021-06-08 | I29: 111149 | J29: Mumbai | K29: jane.das28@example.com | L29: Active | M29: =VLOOKUP(F29,Departments!$A$1:$C$6,2,0) -> Finance | N29: =INDEX(Departments!$B$1:$B$6, MATCH(Employees!F29, Departments!$A$1:$A$6, 0)) -> Finance | O29: =INDEX(Departments!$B$2:$B$6,MATCH(Employees!F29,Departments!$A$2:$A$6,0)) -> Finance | P29: =INDEX(Performance!$C$2:$C$501,MATCH(Employees!A29,Performance!$A$2:$A$501,0)) -> 4 | Q29: =IF(P29=5,I29*0.15,IF(P29=4,I29*0.1,IF(P29=3,I29*0.07,IF(P29<3,I29*0.05,0)))) -> 11114.9
A30: E0029 | B30: Sara | C30: Khan | D30: Male | E30: 36 | F30: D04 | G30: Analyst | H30: 2022-02-08 | I30: 67035 | J30: Mumbai | K30: sara.khan29@example.com | L30: Inactive | M30: =VLOOKUP(F30,Departments!$A$1:$C$6,2,0) -> Sales | N30: =INDEX(Departments!$B$1:$B$6, MATCH(Employees!F30, Departments!$A$1:$A$6, 0)) -> Sales | O30: =INDEX(Departments!$B$2:$B$6,MATCH(Employees!F30,Departments!$A$2:$A$6,0)) -> Sales | P30: =INDEX(Performance!$C$2:$C$501,MATCH(Employees!A30,Performance!$A$2:$A$501,0)) -> 5 | Q30: =IF(P30=5,I30*0.15,IF(P30=4,I30*0.1,IF(P30=3,I30*0.07,IF(P30<3,I30*0.05,0)))) -> 10055.25
A31: E0030 | B31: David | C31: Dutta | D31: Male | E31: 41 | F31: D03 | G31: Analyst | H31: 2021-05-20 | I31: 103851 | J31: Pune | K31: david.dutta30@example.com | L31: Inactive | M31: =VLOOKUP(F31,Departments!$A$1:$C$6,2,0) -> IT | N31: =INDEX(Departments!$B$1:$B$6, MATCH(Employees!F31, Departments!$A$1:$A$6, 0)) -> IT | O31: =INDEX(Departments!$B$2:$B$6,MATCH(Employees!F31,Departments!$A$2:$A$6,0)) -> IT | P31: =INDEX(Performance!$C$2:$C$501,MATCH(Employees!A31,Performance!$A$2:$A$501,0)) -> 2 | Q31: =IF(P31=5,I31*0.15,IF(P31=4,I31*0.1,IF(P31=3,I31*0.07,IF(P31<3,I31*0.05,0)))) -> 5192.55
A32: E0031 | B32: Amit | C32: Ghosh | D32: Female | E32: 26 | F32: D05 | G32: Specialist | H32: 2019-08-08 | I32: 63676 | J32: Kolkata | K32: amit.ghosh31@example.com | L32: Inactive | M32: =VLOOKUP(F32,Departments!$A$1:$C$6,2,0) -> Marketing | N32: =INDEX(Departments!$B$1:$B$6, MATCH(Employees!F32, Departments!$A$1:$A$6, 0)) -> Marketing | O32: =INDEX(Departments!$B$2:$B$6,MATCH(Employees!F32,Departments!$A$2:$A$6,0)) -> Marketing | P32: =INDEX(Performance!$C$2:$C$501,MATCH(Employees!A32,Performance!$A$2:$A$501,0)) -> 1 | Q32: =IF(P32=5,I32*0.15,IF(P32=4,I32*0.1,IF(P32=3,I32*0.07,IF(P32<3,I32*0.05,0)))) -> 3183.8
A33: E0032 | B33: Neha | C33: Smith | D33: Female | E33: 31 | F33: D01 | G33: Manager | H33: 2019-11-15 | I33: 115269 | J33: Mumbai | K33: neha.smith32@example.com | L33: Inactive | M33: =VLOOKUP(F33,Departments!$A$1:$C$6,2,0) -> HR | N33: =INDEX(Departments!$B$1:$B$6, MATCH(Employees!F33, Departments!$A$1:$A$6, 0)) -> HR | O33: =INDEX(Departments!$B$2:$B$6,MATCH(Employees!F33,Departments!$A$2:$A$6,0)) -> HR | P33: =INDEX(Performance!$C$2:$C$501,MATCH(Employees!A33,Performance!$A$2:$A$501,0)) -> 4 | Q33: =IF(P33=5,I33*0.15,IF(P33=4,I33*0.1,IF(P33=3,I33*0.07,IF(P33<3,I33*0.05,0)))) -> 11526.9
A34: E0033 | B34: Neha | C34: Singh | D34: Male | E34: 47 | F34: D04 | G34: Analyst | H34: 2019-06-18 | I34: 77203 | J34: Pune | K34: neha.singh33@example.com | L34: Active | M34: =VLOOKUP(F34,Departments!$A$1:$C$6,2,0) -> Sales | N34: =INDEX(Departments!$B$1:$B$6, MATCH(Employees!F34, Departments!$A$1:$A$6, 0)) -> Sales | O34: =INDEX(Departments!$B$2:$B$6,MATCH(Employees!F34,Departments!$A$2:$A$6,0)) -> Sales | P34: =INDEX(Performance!$C$2:$C$501,MATCH(Employees!A34,Performance!$A$2:$A$501,0)) -> 5 | Q34: =IF(P34=5,I34*0.15,IF(P34=4,I34*0.1,IF(P34=3,I34*0.07,IF(P34<3,I34*0.05,0)))) -> 11580.45
A35: E0034 | B35: John | C35: Sen | D35: Male | E35: 57 | F35: D01 | G35: Specialist | H35: 2024-03-15 | I35: 113291 | J35: Mumbai | K35: john.sen34@example.com | L35: Inactive | M35: =VLOOKUP(F35,Departments!$A$1:$C$6,2,0) -> HR | N35: =INDEX(Departments!$B$1:$B$6, MATCH(Employees!F35, Departments!$A$1:$A$6, 0)) -> HR | O35: =INDEX(Departments!$B$2:$B$6,MATCH(Employees!F35,Departments!$A$2:$A$6,0)) -> HR | P35: =INDEX(Performance!$C$2:$C$501,MATCH(Employees!A35,Performance!$A$2:$A$501,0)) -> 1 | Q35: =IF(P35=5,I35*0.15,IF(P35=4,I35*0.1,IF(P35=3,I35*0.07,IF(P35<3,I35*0.05,0)))) -> 5664.55
A36: E0035 | B36: David | C36: Khan | D36: Female | E36: 45 | F36: D01 | G36: Analyst | H36: 2021-11-25 | I36: 93729 | J36: Mumbai | K36: david.khan35@example.com | L36: Inactive | M36: =VLOOKUP(F36,Departments!$A$1:$C$6,2,0) -> HR | N36: =INDEX(Departments!$B$1:$B$6, MATCH(Employees!F36, Departments!$A$1:$A$6, 0)) -> HR | O36: =INDEX(Departments!$B$2:$B$6,MATCH(Employees!F36,Departments!$A$2:$A$6,0)) -> HR | P36: =INDEX(Performance!$C$2:$C$501,MATCH(Employees!A36,Performance!$A$2:$A$501,0)) -> 5 | Q36: =IF(P36=5,I36*0.15,IF(P36=4,I36*0.1,IF(P36=3,I36*0.07,IF(P36<3,I36*0.05,0)))) -> 14059.35
A37: E0036 | B37: Rohit | C37: Ghosh | D37: Male | E37: 40 | F37: D05 | G37: Specialist | H37: 2018-06-15 | I37: 35947 | J37: Bengaluru | K37: rohit.ghosh36@example.com | L37: Inactive | M37: =VLOOKUP(F37,Departments!$A$1:$C$6,2,0) -> Marketing | N37: =INDEX(Departments!$B$1:$B$6, MATCH(Employees!F37, Departments!$A$1:$A$6, 0)) -> Marketing | O37: =INDEX(Departments!$B$2:$B$6,MATCH(Employees!F37,Departments!$A$2:$A$6,0)) -> Marketing | P37: =INDEX(Performance!$C$2:$C$501,MATCH(Employees!A37,Performance!$A$2:$A$501,0)) -> 1 | Q37: =IF(P37=5,I37*0.15,IF(P37=4,I37*0.1,IF(P37=3,I37*0.07,IF(P37<3,I37*0.05,0)))) -> 1797.35
... A107: E0106 | B107: Neha | C107: Ghosh | D107: Male | E107: 27 | F107: D02 | G107: Analyst | H107: 2023-02-21 | I107: 52495 | J107: Bengaluru | K107: neha.ghosh106@example.com | L107: Active | M107: =VLOOKUP(F107,Departments!$A$1:$C$6,2,0) -> Finance | N107: =INDEX(Departments!$B$1:$B$6, MATCH(Employees!F107, Departments!$A$1:$A$6, 0)) -> Finance | O107: =INDEX(Departments!$B$2:$B$6,MATCH(Employees!F107,Departments!$A$2:$A$6,0)) -> Finance | P107: =INDEX(Performance!$C$2:$C$501,MATCH(Employees!A107,Performance!$A$2:$A$501,0)) -> 5 | Q107: =IF(P107=5,I107*0.15,IF(P107=4,I107*0.1,IF(P107=3,I107*0.07,IF(P107<3,I107*0.05,0)))) -> 7874.25
A108: E0107 | B108: Neha | C108: Singh | D108: Male | E108: 27 | F108: D04 | G108: Analyst | H108: 2019-04-27 | I108: 90958 | J108: Kolkata | K108: neha.singh107@example.com | L108: Inactive | M108: =VLOOKUP(F108,Departments!$A$1:$C$6,2,0) -> Sales | N108: =INDEX(Departments!$B$1:$B$6, MATCH(Employees!F108, Departments!$A$1:$A$6, 0)) -> Sales | O108: =INDEX(Departments!$B$2:$B$6,MATCH(Employees!F108,Departments!$A$2:$A$6,0)) -> Sales | P108: =_xlfn.XLOOKUP(A108,Performance!$A$2:$A$501,Performance!$C$2:$C$501) -> 1 | Q108: =IF(P108=5,I108*0.15,IF(P108=4,I108*0.1,IF(P108=3,I108*0.07,IF(P108<3,I108*0.05,0)))) -> 4547.9
A109: E0108 | B109: Neha | C109: Sen | D109: Female | E109: 58 | F109: D05 | G109: Manager | H109: 2018-08-15 | I109: 51096 | J109: Kolkata | K109: neha.sen108@example.com | L109: Inactive | M109: =VLOOKUP(F109,Departments!$A$1:$C$6,2,0) -> Marketing | N109: =INDEX(Departments!$B$1:$B$6, MATCH(Employees!F109, Departments!$A$1:$A$6, 0)) -> Marketing | O109: =INDEX(Departments!$B$2:$B$6,MATCH(Employees!F109,Departments!$A$2:$A$6,0)) -> Marketing | P109: =INDEX(Performance!$C$2:$C$501,MATCH(Employees!A109,Performance!$A$2:$A$501,0)) -> 1 | Q109: =IF(P109=5,I109*0.15,IF(P109=4,I109*0.1,IF(P109=3,I109*0.07,IF(P109<3,I109*0.05,0)))) -> 2554.8
A110: E0109 | B110: John | C110: Smith | D110: Female | E110: 58 | F110: D02 | G110: Specialist | H110: 2019-02-22 | I110: 90458 | J110: Kolkata | K110: john.smith109@example.com | L110: Active | M110: =VLOOKUP(F110,Departments!$A$1:$C$6,2,0) -> Finance | N110: =INDEX(Departments!$B$1:$B$6, MATCH(Employees!F110, Departments!$A$1:$A$6, 0)) -> Finance | O110: =INDEX(Departments!$B$2:$B$6,MATCH(Employees!F110,Departments!$A$2:$A$6,0)) -> Finance | P110: =INDEX(Performance!$C$2:$C$501,MATCH(Employees!A110,Performance!$A$2:$A$501,0)) -> 3 | Q110: =IF(P110=5,I110*0.15,IF(P110=4,I110*0.1,IF(P110=3,I110*0.07,IF(P110<3,I110*0.05,0)))) -> 6332.06
A111: E0110 | B111: Neha | C111: Das | D111: Male | E111: 39 | F111: D04 | G111: Analyst | H111: 2019-03-13 | I111: 67338 | J111: Pune | K111: neha.das110@example.com | L111: Inactive | M111: =VLOOKUP(F111,Departments!$A$1:$C$6,2,0) -> Sales | N111: =INDEX(Departments!$B$1:$B$6, MATCH(Employees!F111, Departments!$A$1:$A$6, 0)) -> Sales | O111: =INDEX(Departments!$B$2:$B$6,MATCH(Employees!F111,Departments!$A$2:$A$6,0)) -> Sales | P111: =INDEX(Performance!$C$2:$C$501,MATCH(Employees!A111,Performance!$A$2:$A$501,0)) -> 4 | Q111: =IF(P111=5,I111*0.15,IF(P111=4,I111*0.1,IF(P111=3,I111*0.07,IF(P111<3,I111*0.05,0)))) -> 6733.8
A112: E0111 | B112: Amit | C112: Dutta | D112: Female | E112: 40 | F112: D03 | G112: Manager | H112: 2021-10-01 | I112: 106100 | J112: Pune | K112: amit.dutta111@example.com | L112: Inactive | M112: =VLOOKUP(F112,Departments!$A$1:$C$6,2,0) -> IT | N112: =INDEX(Departments!$B$1:$B$6, MATCH(Employees!F112, Departments!$A$1:$A$6, 0)) -> IT | O112: =INDEX(Departments!$B$2:$B$6,MATCH(Employees!F112,Departments!$A$2:$A$6,0)) -> IT | P112: =INDEX(Performance!$C$2:$C$501,MATCH(Employees!A112,Performance!$A$2:$A$501,0)) -> 5 | Q112: =IF(P112=5,I112*0.15,IF(P112=4,I112*0.1,IF(P112=3,I112*0.07,IF(P112<3,I112*0.05,0)))) -> 15915
A113: E0112 | B113: Amit | C113: Khan | D113: Male | E113: 45 | F113: D01 | G113: Analyst | H113: 2021-10-28 | I113: 62840 | J113: Delhi | K113: amit.khan112@example.com | L113: Inactive | M113: =VLOOKUP(F113,Departments!$A$1:$C$6,2,0) -> HR | N113: =INDEX(Departments!$B$1:$B$6, MATCH(Employees!F113, Departments!$A$1:$A$6, 0)) -> HR | O113: =INDEX(Departments!$B$2:$B$6,MATCH(Employees!F113,Departments!$A$2:$A$6,0)) -> HR | P113: =INDEX(Performance!$C$2:$C$501,MATCH(Employees!A113,Performance!$A$2:$A$501,0)) -> 2 | Q113: =IF(P113=5,I113*0.15,IF(P113=4,I113*0.1,IF(P113=3,I113*0.07,IF(P113<3,I113*0.05,0)))) -> 3142
A114: E0113 | B114: Anita | C114: Das | D114: Male | E114: 48 | F114: D01 | G114: Coordinator | H114: 2018-06-23 | I114: 69569 | J114: Pune | K114: anita.das113@example.com | L114: Inactive | M114: =VLOOKUP(F114,Departments!$A$1:$C$6,2,0) -> HR | N114: =INDEX(Departments!$B$1:$B$6, MATCH(Employees!F114, Departments!$A$1:$A$6, 0)) -> HR | O114: =INDEX(Departments!$B$2:$B$6,MATCH(Employees!F114,Departments!$A$2:$A$6,0)) -> HR | P114: =INDEX(Performance!$C$2:$C$501,MATCH(Employees!A114,Performance!$A$2:$A$501,0)) -> 5 | Q114: =IF(P114=5,I114*0.15,IF(P114=4,I114*0.1,IF(P114=3,I114*0.07,IF(P114<3,I114*0.05,0)))) -> 10435.35
A115: E0114 | B115: David | C115: Smith | D115: Female | E115: 23 | F115: D04 | G115: Analyst | H115: 2024-07-09 | I115: 109099 | J115: Mumbai | K115: david.smith114@example.com | L115: Active | M115: =VLOOKUP(F115,Departments!$A$1:$C$6,2,0) -> Sales | N115: =INDEX(Departments!$B$1:$B$6, MATCH(Employees!F115, Departments!$A$1:$A$6, 0)) -> Sales | O115: =INDEX(Departments!$B$2:$B$6,MATCH(Employees!F115,Departments!$A$2:$A$6,0)) -> Sales | P115: =INDEX(Performance!$C$2:$C$501,MATCH(Employees!A115,Performance!$A$2:$A$501,0)) -> 3 | Q115: =IF(P115=5,I115*0.15,IF(P115=4,I115*0.1,IF(P115=3,I115*0.07,IF(P115<3,I115*0.05,0)))) -> 7636.93
A116: E0115 | B116: Sara | C116: Roy | D116: Female | E116: 30 | F116: D03 | G116: Manager | H116: 2022-01-27 | I116: 74368 | J116: Delhi | K116: sara.roy115@example.com | L116: Inactive | M116: =VLOOKUP(F116,Departments!$A$1:$C$6,2,0) -> IT | N116: =INDEX(Departments!$B$1:$B$6, MATCH(Employees!F116, Departments!$A$1:$A$6, 0)) -> IT | O116: =INDEX(Departments!$B$2:$B$6,MATCH(Employees!F116,Departments!$A$2:$A$6,0)) -> IT | P116: =INDEX(Performance!$C$2:$C$501,MATCH(Employees!A116,Performance!$A$2:$A$501,0)) -> 1 | Q116: =IF(P116=5,I116*0.15,IF(P116=4,I116*0.1,IF(P116=3,I116*0.07,IF(P116<3,I116*0.05,0)))) -> 3718.4
A117: E0116 | B117: Rohit | C117: Das | D117: Male | E117: 58 | F117: D05 | G117: Coordinator | H117: 2021-03-04 | I117: 111621 | J117: Delhi | K117: rohit.das116@example.com | L117: Active | M117: =VLOOKUP(F117,Departments!$A$1:$C$6,2,0) -> Marketing | N117: =INDEX(Departments!$B$1:$B$6, MATCH(Employees!F117, Departments!$A$1:$A$6, 0)) -> Marketing | O117: =INDEX(Departments!$B$2:$B$6,MATCH(Employees!F117,Departments!$A$2:$A$6,0)) -> Marketing | P117: =INDEX(Performance!$C$2:$C$501,MATCH(Employees!A117,Performance!$A$2:$A$501,0)) -> 5 | Q117: =IF(P117=5,I117*0.15,IF(P117=4,I117*0.1,IF(P117=3,I117*0.07,IF(P117<3,I117*0.05,0)))) -> 16743.15
...

Sheet Departments
A1: DepartmentID | B1: DepartmentName | C1: Manager | D1: AVERAGE SALARY (Q4)
A2: D01 | B2: HR | C2: Alice | D2: =AVERAGEIF(Employees!$F$2:$F$501,A2,Employees!$I$2:$I$501) -> 79005.776
A3: D02 | B3: Finance | C3: Bob | D3: =AVERAGEIF(Employees!$F$2:$F$501,A3,Employees!$I$2:$I$501) -> 80100.778
A4: D03 | B4: IT | C4: Carol | D4: =AVERAGEIF(Employees!$F$2:$F$501,A4,Employees!$I$2:$I$501) -> 78230.108
A5: D04 | B5: Sales | C5: Dan | D5: =AVERAGEIF(Employees!$F$2:$F$501,A5,Employees!$I$2:$I$501) -> 76510.454
A6: D05 | B6: Marketing | C6: Eva | D6: =AVERAGEIF(Employees!$F$2:$F$501,A6,Employees!$I$2:$I$501) -> 74376.867

Sheet Performance
A1: EmployeeID | B1: ReviewYear | C1: Rating | D1: TrainingHours | E1: ProjectsCompleted
A2: E0001 | B2: 2026 | C2: 1 | D2: 4 | E2: 2
A3: E0002 | B3: 2026 | C3: 4 | D3: 5 | E3: 7
A4: E0003 | B4: 2026 | C4: 2 | D4: 29 | E4: 5
A5: E0004 | B5: 2026 | C5: 4 | D5: 18 | E5: 6
A6: E0005 | B6: 2026 | C6: 2 | D6: 48 | E6: 2
A7: E0006 | B7: 2026 | C7: 3 | D7: 14 | E7: 5
A8: E0007 | B8: 2026 | C8: 2 | D8: 19 | E8: 3
A9: E0008 | B9: 2026 | C9: 1 | D9: 4 | E9: 2
A10: E0009 | B10: 2026 | C10: 4 | D10: 59 | E10: 0
A11: E0010 | B11: 2026 | C11: 5 | D11: 27 | E11: 2
A12: E0011 | B12: 2026 | C12: 3 | D12: 42 | E12: 3
A13: E0012 | B13: 2026 | C13: 2 | D13: 59 | E13: 3
... A501: E0500 | B501: 2026 | C501: 3 | D501: 47 | E501: 8

Sheet Summary
A1: Metric | B1: Value
A2: Q5: Count of Active Employees | B2: =COUNTIF(Employees!$L$2:$L$501,"Active") -> 237
A3: Q8: Analysts based in Kolkata (count) | B3: =COUNTIFS(Employees!$G$2:$G$501,"Analyst",Employees!$J$2:$J$501,"Kolkata") -> 17

Sheet Filter
